Workbook

Sheet Summary
A1: Dinner for Two - Seattle Catalog (live coverage)
A2: Verified June 19, 2026. 'Live' = Enriched & web-verified open. Counts auto-update from the Restaurants sheet.
A4: Status | B4: Count
A5: Live (Enriched) | B5: =COUNTIF(Restaurants!$AK$3:$AK$98,"Enriched") -> 71
A6: Closed - drop | B6: =COUNTIF(Restaurants!$AK$3:$AK$98,"CLOSED - drop") -> 17
A7: Needs review | B7: =COUNTIF(Restaurants!$AK$3:$AK$98,"Review") -> 8
A8: TOTAL | B8: =COUNTA(Restaurants!$C$3:$C$98) -> 96
A10: Live by Neighborhood | D10: Live by Price Tier
A11: Neighborhood | B11: Live | D11: Tier | E11: Live
A12: Capitol Hill | B12: =COUNTIFS(Restaurants!$C$3:$C$98,"Capitol Hill",Restaurants!$AK$3:$AK$98,"Enriched") -> 8 | D12: $ | E12: =COUNTIFS(Restaurants!$F$3:$F$98,"$",Restaurants!$AK$3:$AK$98,"Enriched") -> 7
A13: Ballard | B13: =COUNTIFS(Restaurants!$C$3:$C$98,"Ballard",Restaurants!$AK$3:$AK$98,"Enriched") -> 6 | D13: $$ | E13: =COUNTIFS(Restaurants!$F$3:$F$98,"$$",Restaurants!$AK$3:$AK$98,"Enriched") -> 22
A14: Belltown | B14: =COUNTIFS(Restaurants!$C$3:$C$98,"Belltown",Restaurants!$AK$3:$AK$98,"Enriched") -> 6 | D14: $$$ | E14: =COUNTIFS(Restaurants!$F$3:$F$98,"$$$",Restaurants!$AK$3:$AK$98,"Enriched") -> 35
A15: Fremont | B15: =COUNTIFS(Restaurants!$C$3:$C$98,"Fremont",Restaurants!$AK$3:$AK$98,"Enriched") -> 5 | D15: $$$$ | E15: =COUNTIFS(Restaurants!$F$3:$F$98,"$$$$",Restaurants!$AK$3:$AK$98,"Enriched") -> 7
A16: Downtown | B16: =COUNTIFS(Restaurants!$C$3:$C$98,"Downtown",Restaurants!$AK$3:$AK$98,"Enriched") -> 3
A17: Pike Place | B17: =COUNTIFS(Restaurants!$C$3:$C$98,"Pike Place",Restaurants!$AK$3:$AK$98,"Enriched") -> 6
A18: Queen Anne | B18: =COUNTIFS(Restaurants!$C$3:$C$98,"Queen Anne",Restaurants!$AK$3:$AK$98,"Enriched") -> 7 | D18: Live by Date-Night Score
A19: Wallingford | B19: =COUNTIFS(Restaurants!$C$3:$C$98,"Wallingford",Restaurants!$AK$3:$AK$98,"Enriched") -> 7 | D19: Score | E19: Live
A20: Madrona | B20: =COUNTIFS(Restaurants!$C$3:$C$98,"Madrona",Restaurants!$AK$3:$AK$98,"Enriched") -> 5 | D20: 5 | E20: =COUNTIFS(Restaurants!$U$3:$U$98,5,Restaurants!$AK$3:$AK$98,"Enriched") -> 7
A21: Madrona-adjacent | B21: =COUNTIFS(Restaurants!$C$3:$C$98,"Madrona-adjacent",Restaurants!$AK$3:$AK$98,"Enriched") -> 3 | D21: 4 | E21: =COUNTIFS(Restaurants!$U$3:$U$98,4,Restaurants!$AK$3:$AK$98,"Enriched") -> 33
A22: Phinney Ridge | B22: =COUNTIFS(Restaurants!$C$3:$C$98,"Phinney Ridge",Restaurants!$AK$3:$AK$98,"Enriched") -> 3 | D22: 3 | E22: =COUNTIFS(Restaurants!$U$3:$U$98,3,Restaurants!$AK$3:$AK$98,"Enriched") -> 21
A23: Greenwood | B23: =COUNTIFS(Restaurants!$C$3:$C$98,"Greenwood",Restaurants!$AK$3:$AK$98,"Enriched") -> 3 | D23: 2 | E23: =COUNTIFS(Restaurants!$U$3:$U$98,2,Restaurants!$AK$3:$AK$98,"Enriched") -> 10
A24: U District | B24: =COUNTIFS(Restaurants!$C$3:$C$98,"U District",Restaurants!$AK$3:$AK$98,"Enriched") -> 9

Sheet Restaurants
A1: SEED — you fill (min: Name, Neighborhood, URL) | H1: ENRICHMENT — Claude fills from websites + review/Google cross-check
A2: ID | B2: Restaurant Name * | C2: Neighborhood * | D2: Website URL * | E2: Cuisine (Primary) | F2: Price Tier | G2: Tags (your notes) | H2: Description | I2: Venue Type | J2: Address | K2: Phone | L2: Cuisine (Secondary) | M2: Dinner Hours | N2: Reservations | O2: Reservation Platform | P2: Vegetarian | Q2: Vegan | R2: Gluten-Free | S2: Ambiance Tags | T2: Noise Level | U2: Date-Night Score (1-5) | V2: Outdoor Seating | W2: Rating | X2: Rating Count | Y2: Review Snippet | Z2: Hero Dish 1 | AA2: Hero Dish 2 | AB2: Avg Entree Price | AC2: Menu URL | AD2: Menu Format | AE2: Menu File (local) | AF2: Photo URL | AG2: Latitude | AH2: Longitude | AI2: Menu Last Updated | AJ2: Verified Date | AK2: Enrichment Status
A3: 1 | B3: Spinasse | C3: Capitol Hill | D3: https://www.spinasse.com | E3: Italian | F3: $$$$ | G3: cozy;romantic;handmade-pasta | H3: Cascina Spinasse is Capitol Hill's temple to Piedmontese cooking, famous for tajarin — hand-cut egg pasta in butter and sage, almost translucent. The room is small, candlelit, and unapologetically romantic: the place you book when the night is supposed to matter. | I3: Restaurant | J3: 1531 14th Ave, Seattle, WA 98122 | K3: (206) 251-7673 | L3: Piedmontese | M3: Sun-Thu 5-10pm; Fri-Sat 5-11pm | N3: Yes | O3: Tock/Direct | P3: Y | Q3: N | R3: N | S3: Romantic; Candlelit; Intimate | T3: Moderate | U3: 5 | V3: N | X3: 1500+ | Y3: Award-winning Piemontese; hand-cut tajarin is the signature | Z3: Tajarin al burro e salvia | AA3: Agnolotti dal plin | AB3: $100+ a la carte | AC3: https://spinasse.com/menu/ | AD3: HTML | AI3: 2026-06 | AJ3: 2026-06-19 | AK3: Enriched
A4: 2 | B4: Artusi | C4: Capitol Hill | D4: https://www.artusibar.com | E4: Italian | F4: $$ | G4: cocktails;intimate | H4: Artusi is Spinasse's next-door aperitivo bar, grown into its own draw — negronis, Italian small plates, and a buzzy 21-and-over room. Walk in for a pre-dinner spritz or stay the night; it's flirtier and louder than its sibling, built for a date with momentum. | I4: Bar | J4: 1535 14th Ave, Seattle, WA 98122 | K4: (206) 678-8593 | L4: Aperitivo/Small plates | M4: Daily 5-10pm (Fri-Sat to 11) | N4: Walk-in | O4: Walk-in (res 3+) | P4: Y | Q4: N | R4: Y | S4: Lively; Stylish; Date-friendly | T4: Loud | U4: 4 | V4: N | X4: 350+ | Y4: Spinasse's aperitivo bar; cocktails + Italian snacks, 21+ | Z4: Negroni | AA4: Seasonal cicchetti | AB4: $25-40 | AC4: https://artusibar.com/ | AD4: HTML | AI4: 2026-06 | AJ4: 2026-06-19 | AK4: Enriched
A5: 3 | B5: Taurus Ox | C5: Capitol Hill | D5: https://www.taurusox.com | E5: Laotian | F5: $$ | G5: spicy;hip | H5: Taurus Ox brings Laotian cooking rarely found in Seattle to a petite Capitol Hill room — fermented, herbal, chili-bright. Lao sausage, braised pork-belly thom khem, a cult Lao burger. No reservations and a little tight on tables; right for a casual, adventurous date. | I5: Restaurant | J5: 903 19th Ave E, Seattle, WA 98112 | K5: (206) 466-2785 | L5: Laotian | M5: Tue-Sat 11-2pm & 5-9pm | N5: Walk-in | O5: Waitlist at door | P5: Y | Q5: Y | R5: Y | S5: Hip; Cozy; Casual | T5: Moderate | U5: 3 | V5: N | X5: 590+ | Y5: Rare Laotian menu; Lao sausage and thom khem are standouts | Z5: Lao sausage | AA5: Thom khem (braised pork belly) | AB5: $15-25 | AC5: https://www.taurusox.com/ | AD5: HTML | AI5: 2026-06 | AJ5: 2026-06-19 | AK5: Enriched
A6: 4 | B6: Momiji | C6: Capitol Hill | D6: https://www.momijiseattle.com | E6: Japanese/Sushi | F6: $$$ | G6: garden;cozy | H6: Momiji hides a serene courtyard garden behind a busy Capitol Hill block — the rare sushi room that feels like an escape. Order omakase or work the roll list; the back patio under string lights is one of the neighborhood's quietly romantic seats. Open late for a spontaneous night. | I6: Restaurant | J6: 1522 12th Ave, Seattle, WA 98122 | K6: (206) 457-4068 | L6: Sushi/Omakase | M6: Daily 4pm-12am | N6: Yes | O6: OpenTable | P6: Y | Q6: N | R6: Y | S6: Garden patio; Cozy; Romantic | T6: Moderate | U6: 4 | V6: Y | X6: 2000+ | Y6: Sushi & omakase around a hidden courtyard garden | Z6: Omakase | AA6: Capitol Hill Roll | AB6: $30-50 | AC6: https://www.momijiseattle.com/ | AD6: HTML | AI6: 2026-06 | AJ6: 2026-06-19 | AK6: Enriched
A7: 5 | B7: Terra Plata | C7: Capitol Hill | D7: https://www.terraplata.com | E7: Pacific NW | F7: $$$ | G7: rooftop;seasonal | H7: Terra Plata is Tamara Murphy's earth-to-plate room crowned by a covered, heated rooftop garden — greenery, herbs, and one of Capitol Hill's best al-fresco perches. The menu shifts with the season and leans Mediterranean; Monday paella night is the local ritual. Book the roof when weather turns. | I7: Restaurant | J7: 1501 Melrose Ave, Seattle, WA 98122 | K7: (206) 325-1501 | L7: Farm-to-table/Mediterranean | M7: Mon-Fri 4-10pm; Sat 9:30am-10pm; Sun 9:30am-9pm | N7: Yes | O7: OpenTable | P7: Y | Q7: Y | R7: Y | S7: Rooftop garden; Charming; Seasonal | T7: Moderate | U7: 4 | V7: Y | X7: 1300+ | Y7: James Beard chef Tamara Murphy; rooftop garden, Monday paella | Z7: Paella (Mon night) | AA7: Seasonal market plates | AB7: $30-50 | AC7: https://www.terraplata.com/ | AD7: HTML | AI7: 2026-06 | AJ7: 2026-06-19 | AK7: Enriched
A8: 6 | B8: Rione XIII | C8: Capitol Hill | D8: https://www.ethanstowellrestaurants.com | E8: Italian | F8: $$$ | G8: neighborhood;wine | H8: Rione XIII channels Rome's Trastevere on 15th Ave — fried artichokes, cacio e pepe, carbonara, and blistered Roman pizza, with a wine list to match. It's the Ethan Stowell room that feels most like a neighborhood trattoria: lively, warm, and easy to linger in. Reservations smooth the wait. | I8: Restaurant | J8: 401 15th Ave E, Seattle, WA 98112 | K8: (206) 838-2878 | L8: Roman | M8: Daily 5-10pm | N8: Yes | O8: OpenTable | P8: Y | Q8: N | R8: N | S8: Neighborhood; Warm; Wine-focused | T8: Moderate | U8: 4 | V8: N | X8: 490+ | Y8: Roman cuisine & wood-fired pizza, Ethan Stowell trattoria | Z8: Cacio e pepe | AA8: Roman-style pizza | AB8: $30-45 | AC8: https://ethanstowellrestaurants.com/restaurants/rione-xiii-capitol-hill-seattle | AD8: HTML | AI8: 2026-06 | AJ8: 2026-06-19 | AK8: Enriched
A9: 7 | B9: Altura | C9: Capitol Hill | D9: https://www.alturarestaurant.com | E9: Italian Tasting Menu | F9: $$$$ | G9: tasting-menu;special-occasion | H9: Altura is Capitol Hill's special-occasion summit — Nathan Lockwood's weekly-changing Italian-Pacific Northwest tasting menu in a hushed, candlelit room over a long, unhurried evening. At $137 a person it's a commitment, and the kind of night you book when the occasion deserves one. Reserve directly. | I9: Restaurant | J9: 617 Broadway E, Seattle, WA 98102 | K9: (206) 402-6749 | L9: Italian-PNW tasting | M9: Tue-Thu 5:30-10pm; Fri-Sat 5-10pm | N9: Yes | O9: Direct (not OpenTable) | P9: Y | Q9: N | R9: Y | S9: Romantic; Hushed; Special-occasion | T9: Quiet | U9: 5 | V9: N | X9: 700+ | Y9: Weekly-changing Italian-PNW tasting menu, $137pp | Z9: Chef's tasting menu | AA9: Handmade pasta course | AB9: $137 prix fixe | AC9: https://alturarestaurant.com/ | AD9: HTML | AI9: 2026-06 | AJ9: 2026-06-19 | AK9: Enriched
A10: 8 | B10: Jeffry's (formerly Bateau) | C10: Capitol Hill | D10: https://www.sea-creatures.com/ | E10: Steakhouse | F10: $$$ | G10: craft-butchery;romantic | H10: Jeffry's is the 2026 reboot of Renee Erickson's beloved Bateau — same in-house dry-aged beef, leaner and more approachable, with a 'Humble Cuts' menu of lesser-known cuts. The intimate Union St room still reads like a date-night steakhouse, just with a friendlier check. Wednesday through Sunday only. | I10: Restaurant | J10: 1040 E Union St, Seattle, WA 98122 | K10: (206) 900-8699 | L10: Dry-aged steakhouse | M10: Wed-Sun 5-9pm | N10: Yes | O10: Resy | P10: N | Q10: N | R10: Y | S10: Intimate; Romantic; Refined | T10: Moderate | U10: 4 | V10: N | X10: 430+ | Y10: Renee Erickson dry-aged steakhouse, reopened 2026 as Jeffry's | Z10: Dry-aged steak | AA10: Humble Cuts selection | AB10: $45-70 | AC10: https://www.sea-creatures.com/ | AD10: HTML | AI10: 2026-06 | AJ10: 2026-06-19 | AK10: Enriched
A11: 9 | B11: Stateside | C11: Capitol Hill | D11: https://www.statesideseattle.com | E11: Vietnamese-French | G11: bright;date-friendly | I11: Restaurant | AK11: CLOSED - drop
A12: 10 | B12: Witness | C12: Capitol Hill | D12: https://www.witnessbar.com | E12: Southern | G12: cocktails;intimate | I12: Restaurant | AK12: CLOSED - drop
A13: 11 | B13: San Fermo | C13: Ballard | D13: https://www.sanfermo.com | E13: Italian | F13: $$$ | G13: cozy;romantic | H13: San Fermo is a candlelit cottage on Ballard Ave doing rustic, ingredient-driven Italian — handmade pasta like strozzapreti amatriciana, burrata to start, olive oil cake to finish. The old house feels intimate and a little hidden, the kind of cozy that makes a two-top feel like the only table. Reserve ahead. | I13: Restaurant | J13: 5341 Ballard Ave NW, Seattle, WA 98107 | K13: (206) 342-1530 | L13: Northern Italian | M13: Daily 5-10pm | N13: Yes | O13: OpenTable | P13: Y | Q13: N | R13: N | S13: Cozy; Candlelit; Romantic | T13: Moderate | U13: 4 | V13: N | X13: 670+ | Y13: Cozy Ballard Ave Italian; handmade pasta, local ingredients | Z13: Strozzapreti amatriciana | AA13: Burrata | AB13: $25-40 | AC13: https://www.sanfermo.com | AD13: HTML | AI13: 2026-06 | AJ13: 2026-06-19 | AK13: Enriched
A14: 12 | B14: The Walrus and the Carpenter | C14: Ballard | D14: https://www.thewalrusbar.com | E14: Seafood | F14: $$$ | G14: oysters;intimate | H14: The Walrus and the Carpenter is Renee Erickson's iconic oyster bar — a tiny, candlelit room where the night is built around freshly shucked oysters, steak tartare, and crisp wine. First-come only and always a little buzzy; arrive early and let a date unfold over a tower of ice and a bottle of Muscadet. | I14: Restaurant | J14: 4743 Ballard Ave NW, Seattle, WA 98107 | K14: (206) 395-9227 | L14: Oyster/Raw bar | M14: Sun-Thu 4-9pm; Fri-Sat 4-10pm | N14: Walk-in | O14: First-come, no res | P14: Y | Q14: N | R14: Y | S14: Intimate; Buzzy; Romantic | T14: Loud | U14: 4 | V14: N | X14: 2000+ | Y14: Renee Erickson's celebrated oyster bar; tiny and lively | Z14: Fresh oysters | AA14: Steak tartare | AB14: $40-60 | AC14: https://thewalrusbar.com | AD14: HTML | AI14: 2026-06 | AJ14: 2026-06-19 | AK14: Enriched
A15: 13 | B15: Stoneburner | C15: Ballard | D15: https://www.stoneburnerseattle.com | E15: Italian | F15: $$$ | G15: wood-fired;warm | H15: Stoneburner pairs rustic Italian technique with Pacific Northwest ingredients inside Hotel Ballard — wood-fired vegetables, handmade pasta, blistered pizza in a warm, high-ceilinged room. It's lively without being loud and easy to book, a dependable date that works for a casual Tuesday or a dressed-up Saturday alike. | I15: Restaurant | J15: 5214 Ballard Ave NW, Seattle, WA 98107 | K15: (206) 695-2051 | L15: Italian-PNW; wood-fired | M15: Wed-Sat 4:30-9pm; Sun brunch + 4:30-9pm | N15: Yes | O15: OpenTable | P15: Y | Q15: Y | R15: Y | S15: Warm; Wood-fired; Easy | T15: Moderate | U15: 4 | V15: N | X15: 830+ | Y15: Rustic Italian + PNW in Hotel Ballard; handmade pasta | Z15: Handmade pasta | AA15: Wood-fired pizza | AB15: $25-40 | AC15: https://www.stoneburnerseattle.com/menu | AD15: HTML | AI15: 2026-06 | AJ15: 2026-06-19 | AK15: Enriched
A16: 14 | B16: Bastille Café | C16: Ballard | D16: https://www.bastilleseattle.com | E16: French | G16: patio;romantic | I16: Restaurant | Y16: Closed — space now Sabine Café (possible swap) | AJ16: 2026-06-19 | AK16: CLOSED - drop
A17: 15 | B17: La Carta de Oaxaca | C17: Ballard | D17: https://www.lacartadeoaxaca.com | E17: Mexican | F17: $$ | G17: lively;authentic | H17: La Carta de Oaxaca has anchored Ballard Ave since 2003 with the city's benchmark mole negro, handmade tortillas, and mezcal. It's lively, family-run, and walk-in only, so expect a wait at the bar — part of the charm. A spirited, unfussy date over shared plates and a good cocktail. | I17: Restaurant | J17: 5431 Ballard Ave NW, Seattle, WA 98107 | K17: (206) 782-8722 | L17: Oaxacan | M17: Tue-Thu 11:30am-9:30pm; Fri-Sat to 10:30pm | N17: Walk-in | O17: No res (popular) | P17: Y | Q17: Y | R17: Y | S17: Lively; Authentic; Festive | T17: Loud | U17: 3 | V17: N | X17: 1400+ | Y17: Benchmark Oaxacan; famous mole negro, walk-in only | Z17: Mole negro | AA17: Tacos al pastor | AB17: $15-25 | AC17: https://seattlemeetsoaxaca.com | AD17: HTML | AI17: 2026-06 | AJ17: 2026-06-19 | AK17: Enriched
A18: 16 | B18: Ruam Mit Thai | C18: Ballard | D18: https://www.ruammitthai.com | E18: Thai | G18: casual-date | I18: Restaurant | Y18: Not found in Ballard — verify/likely closed | AJ18: 2026-06-19 | AK18: CLOSED - drop
A19: 17 | B19: Sawyer | C19: Ballard | D19: https://www.sawyerseattle.com | E19: American | G19: creative;fun | I19: Restaurant | Y19: Closed (2026) | AJ19: 2026-06-19 | AK19: CLOSED - drop
A20: 18 | B20: The Ballard Cut | C20: Ballard | D20: https://www.ballardcut.com | E20: Steakhouse | F20: $$$ | G20: whiskey;intimate | H20: The Ballard Cut is a moody steakhouse-meets-whiskey-bar with a 1,200-bottle list — tomahawks, aged New York strip, and a sleeper-hit spicy arrabbiata. Low light, dark wood, and a serious pour make it a grown-up date: order a dry-aged cut, let someone walk you through the rye, and settle in. | I20: Restaurant | J20: 2221 NW Market St, Seattle, WA 98107 | K20: (564) 654-3008 | L20: Steakhouse/New American; whiskey bar | M20: Mon-Thu 4-10pm; Fri-Sat 4-11pm; Sun 4-9pm | N20: Yes | O20: OpenTable | P20: N | Q20: N | R20: Y | S20: Moody; Whiskey; Intimate | T20: Moderate | U20: 4 | V20: N | X20: 320+ | Y20: Steakhouse + 1,200-bottle whiskey bar; tomahawk, aged strip | Z20: Aged New York strip | AA20: Spicy arrabbiata | AB20: $35-60 | AC20: https://theballardcut.com/menu/ | AD20: HTML | AI20: 2026-06 | AJ20: 2026-06-19 | AK20: Enriched
A21: 19 | B21: Ocho | C21: Ballard | D21: https://www.ochoseattle.com | E21: Spanish | F21: $$ | G21: tapas;romantic | H21: Ocho is a tiny Ballard tapas bar built for grazing — patatas bravas, tortilla española, sherried mushrooms on toast, and a deep bench of Spanish wine and sherry. No reservations and elbow-to-elbow, which is exactly why it works for a date: order a dozen small things, share everything, stay late. | I21: Bar | J21: 2325 NW Market St, Seattle, WA 98107 | K21: (206) 784-0699 | L21: Spanish tapas | M21: Daily, dinner to late (to 2am) | N21: Walk-in | O21: No res (text-when-ready) | P21: Y | Q21: Y | R21: Y | S21: Tiny; Romantic; Late-night | T21: Loud | U21: 4 | V21: Y | X21: 680+ | Y21: Tiny Spanish tapas + sherry bar; grazing, no reservations | Z21: Patatas bravas | AA21: Tortilla española | AB21: $15-30 | AC21: https://www.ochoseattle.com | AD21: HTML | AI21: 2026-06 | AJ21: 2026-06-19 | AK21: Enriched
A22: 20 | B22: Shiro's | C22: Belltown | D22: https://www.shiros.com | E22: Japanese/Sushi | F22: $$$$ | G22: classic;chef-driven | H22: Shiro's is Seattle's Edomae sushi institution, founded by the master who put the city's raw-fish scene on the map. Sit at the bar for omakase and watch each piece set down one at a time. Spare, classic, and serious about fish — a refined date for two who'd rather talk over nigiri than noise. | I22: Restaurant | J22: 2401 2nd Ave, Seattle, WA 98121 | K22: (206) 443-9844 | L22: Edomae sushi/Omakase | M22: Daily 4:30-9pm (Fri-Sun to 9:30) | N22: Yes | O22: Resy | P22: N | Q22: N | R22: Y | S22: Classic; Chef-driven; Refined | T22: Quiet | U22: 4 | V22: N | X22: 2800+ | Y22: Seattle's original Edomae sushi; omakase $140, chef's choice $85 | Z22: Omakase | AA22: Nigiri sushi course | AB22: $85-140 omakase | AC22: https://shiros.com/ | AD22: HTML | AI22: 2026-06 | AJ22: 2026-06-19 | AK22: Enriched
A23: 21 | B23: El Gaucho | C23: Belltown | D23: https://www.elgaucho.com | E23: Steakhouse | F23: $$$$ | G23: classic;music | H23: El Gaucho is old-school supper-club theater — tuxedoed servers, tableside Caesar and bananas Foster, 28-day dry-aged beef over a charcoal grill, often a piano in the background. It's a splurge built for an occasion; book a booth, dress up, and lean into the romance of a steakhouse that still performs. | I23: Restaurant | J23: 2200 Western Ave Ste 101, Seattle, WA 98121 | K23: (206) 728-1337 | L23: Dry-aged steakhouse | M23: Tue-Sat 4pm-late (to 9:30/10pm) | N23: Yes | O23: SevenRooms | P23: N | Q23: N | R23: Y | S23: Classic; Theatrical; Special-occasion | T23: Moderate | U23: 5 | V23: N | X23: 1490+ | Y23: Old-school supper club; tableside service, dry-aged beef | Z23: Steak El Gaucho (filet + lobster) | AA23: Bananas Foster (tableside) | AB23: $55-90 | AC23: https://elgaucho.com/seattle/ | AD23: HTML | AI23: 2026-06 | AJ23: 2026-06-19 | AK23: Enriched
A24: 22 | B24: List | C24: Belltown | D24: https://www.listbelltown.com | E24: Italian | G24: small-plates;sexy | I24: Restaurant | Y24: Yelp shows CLOSED (May 2026); OpenTable still lists — verify before include | AJ24: 2026-06-19 | AK24: Review
A25: 23 | B25: Tilikum Place Café | C25: Belltown | D25: https://www.tilikumplacecafe.com | E25: European | F25: $$$ | G25: cozy;brunch-date | H25: Tilikum Place Café is a tucked-away little room by the Chief Sealth fountain, beloved for its giant Dutch baby pancake but quietly excellent at dinner — a short, seasonal European-leaning menu in a warm, intimate space. Dinner runs Thursday through Saturday only, so landing a table feels like a small secret. | I25: Restaurant | J25: 407 Cedar St, Seattle, WA 98121 | K25: (206) 282-4830 | L25: European/New American | M25: Dinner Thu-Sat 5-9pm; weekend brunch | N25: Yes | O25: OpenTable | P25: Y | Q25: N | R25: Y | S25: Cozy; Charming; Intimate | T25: Quiet | U25: 4 | V25: N | X25: 2400+ | Y25: Tucked-away bistro; famed Dutch baby, limited dinner nights | Z25: Seared halibut | AA25: Dutch baby (brunch) | AB25: $25-40 | AC25: https://www.tilikumplacecafe.com/menus | AD25: HTML | AI25: 2026-06 | AJ25: 2026-06-19 | AK25: Enriched
A26: 24 | B26: Umi Sake House | C26: Belltown | D26: https://www.umisakehouse.com | E26: Japanese/Sushi | F26: $$$ | G26: loungey;late-night | H26: Umi Sake House is a buzzy Belltown izakaya — a sprawling sushi list, 60-plus sakes, and a hidden tropical back patio that's the seat to request. It's loud, fun, and open late, the kind of high-energy date where you order too many rolls, work through the sake menu, and stay longer than planned. | I26: Restaurant | J26: 2230 1st Ave, Seattle, WA 98121 | K26: (206) 374-8717 | L26: Izakaya/Sushi | M26: Daily 4pm-11pm (Fri-Sat to 12am) | N26: Yes | O26: OpenTable | P26: Y | Q26: Y | R26: Y | S26: Loungey; Late-night; Buzzy | T26: Loud | U26: 3 | V26: Y | X26: 4300+ | Y26: Big izakaya sushi menu, 60+ sakes, tropical back patio | Z26: Specialty rolls | AA26: Izakaya small plates | AB26: $25-45 | AC26: https://www.umisakehouse.com/menus | AD26: HTML | AI26: 2026-06 | AJ26: 2026-06-19 | AK26: Enriched
A27: 25 | B27: Shaker + Spear | C27: Belltown | D27: https://www.shakerandspear.com | E27: Seafood | F27: $$$ | G27: modern;hotel-date | H27: Shaker + Spear is a polished, market-driven seafood room inside the Kimpton Palladian — Northwest fish, seasonal plates, and a cocktail list worth lingering over in a handsome 1910 building. It's a calm, grown-up hotel-restaurant date: easy to book, quietly stylish, and reliably good without the wait of Ballard's oyster bars. | I27: Restaurant | J27: 2000 2nd Ave, Seattle, WA 98121 | K27: (206) 826-1700 | L27: Pacific NW seafood | M27: Dinner daily 4:45-9pm | N27: Yes | O27: OpenTable | P27: Y | Q27: N | R27: Y | S27: Modern; Polished; Hotel-date | T27: Moderate | U27: 4 | V27: N | X27: 1240+ | Y27: Market-driven NW seafood in the Kimpton Palladian | Z27: Seasonal whole fish | AA27: Seafood tower | AB27: $30-50 | AC27: https://shakerandspear.com/menus | AD27: HTML | AI27: 2026-06 | AJ27: 2026-06-19 | AK27: Enriched
A28: 26 | B28: Local 360 | C28: Belltown | D28: https://www.local360.org | E28: American | G28: farm-to-table | I28: Restaurant | Y28: Closed (2026) | AJ28: 2026-06-19 | AK28: CLOSED - drop
A29: 27 | B29: Black Bottle | C29: Belltown | D29: https://www.blackbottleseattle.com | E29: Gastropub | F29: $$ | G29: lively;shareable | H29: Black Bottle calls itself Seattle's first gastropub — a 21-plus Belltown gastrotavern of shareable plates and craft cocktails: smoked wild boar ribs, bacon-lemon scallops, Spanish-fried olives. Unfussy, lively, and easy on the wallet, it's a low-stakes date that rewards ordering a stack of small plates and a couple of stiff drinks. | I29: Restaurant | J29: 2600 1st Ave, Seattle, WA 98121 | K29: (206) 441-1500 | L29: Gastropub/shared plates | M29: Mon-Sat 4-10pm (Fri-Sat to 11); Sun closed | N29: Yes | O29: OpenTable | P29: Y | Q29: Y | R29: Y | S29: Lively; Shareable; Casual | T29: Loud | U29: 3 | V29: Y | X29: 1220+ | Y29: Seattle's first gastropub; shareable plates, 21+ | Z29: Smoked wild boar ribs | AA29: Bacon-lemon scallops | AB29: $15-30 | AC29: https://www.blackbottleseattle.com/ | AD29: HTML | AI29: 2026-06 | AJ29: 2026-06-19 | AK29: Enriched
A30: 28 | B30: Rob Roy | C30: Belltown | D30: https://www.robroyseattle.com | E30: Cocktail Bar | G30: dark;romantic | I30: Bar | Y30: Cocktail bar, no kitchen (only bar snacks) — exclude per dinner-only rule | AJ30: 2026-06-19 | AK30: Review
A31: 29 | B31: Revel | C31: Fremont | D31: https://www.revelseattle.com | E31: Korean-Fusion | F31: $$ | G31: fun;creative | H31: Revel is Fremont's modern Korean kitchen — short-rib dumplings, scallion-and-kimchi pancakes, and rice and noodle bowls off a menu that turns over monthly. The room is communal and energetic with a sharp cocktail bar attached, a lively, creative date where the food is adventurous but the vibe stays easygoing. | I31: Restaurant | J31: 401 N 36th St, Seattle, WA 98103 | K31: (206) 547-2040 | L31: Korean-American | M31: Tue-Sun 5-9pm (Fri-Sat to 10) | N31: Yes | O31: OpenTable | P31: Y | Q31: Y | R31: Y | S31: Creative; Communal; Energetic | T31: Loud | U31: 4 | V31: Y | X31: 1500+ | Y31: Modern Korean small plates, monthly menu, cocktail bar | Z31: Kimchi-scallion pancake | AA31: Short rib dumplings | AB31: $18-30 | AC31: https://www.revelseattle.com | AD31: HTML | AI31: 2026-06 | AJ31: 2026-06-19 | AK31: Enriched
A32: 30 | B32: Le Coin | C32: Fremont | D32: https://www.lecoinseattle.com | E32: French | F32: $$$ | G32: romantic;neighborhood | H32: Le Coin turned the old Buckaroo Tavern into a buzzy French-leaning bistro — Northwest seafood and game, a great caviar service, and Brussels sprouts people cross town for. Romantic without being stiff, the kind of neighborhood spot that feels like an occasion. Reservations drop on the 15th for the next month, so plan ahead. | I32: Restaurant | J32: 4201 Fremont Ave N, Seattle, WA 98103 | K32: (206) 708-7207 | L32: French/PNW seafood | M32: Dinner nightly 4-9pm (Fri-Sat to 10); brunch Thu-Sun | N32: Yes | O32: Tock | P32: Y | Q32: N | R32: Y | S32: Romantic; Neighborhood-chic; Lively | T32: Moderate | U32: 4 | V32: N | X32: 640+ | Y32: French bistro in old Buckaroo Tavern; caviar, game, seafood | Z32: Caviar service | AA32: Crispy Brussels sprouts | AB32: $30-50 | AC32: https://lecoinseattle.com/ | AD32: HTML | AI32: 2026-06 | AJ32: 2026-06-19 | AK32: Enriched
A33: 31 | B33: Pomerol | C33: Fremont | D33: https://www.pomerolrestaurant.com | E33: French | G33: wood-fired;intimate | I33: Restaurant | Y33: Closed (2026) — space now Meesha 127 (Indian) | AJ33: 2026-06-19 | AK33: CLOSED - drop
A34: 32 | B34: RockCreek | C34: Fremont | D34: https://www.rockcreekseattle.com | E34: Seafood | F34: $$$ | G34: cozy;date-night | H34: RockCreek is a soaring A-frame packed with globally sourced fish — Northwest oysters and crab alongside Hawaiian ono and East Coast striped bass, all arriving daily. Warm, a little loud, and consistently excellent, the reliable Fremont seafood date when you want range beyond the usual oysters and a deep cocktail list. | I34: Restaurant | J34: 4300 Fremont Ave N, Seattle, WA 98103 | K34: (206) 557-7532 | L34: Global seafood | M34: Mon-Fri 4-10pm; Sat-Sun 10am-10pm | N34: Yes | O34: OpenTable | P34: Y | Q34: N | R34: Y | S34: Cozy; Bustling; Date-night | T34: Loud | U34: 4 | V34: Y | X34: 1360+ | Y34: Two-story A-frame; globally sourced fish, daily fresh | Z34: Oysters & shellfish | AA34: Daily fresh fish | AB34: $25-45 | AC34: https://rockcreekseafood.com/seattle-menu/ | AD34: HTML | AI34: 2026-06 | AJ34: 2026-06-19 | AK34: Enriched
A35: 33 | B35: Manolin | C35: Fremont | D35: https://www.manolinseattle.com | E35: Seafood | G35: tropical;bar | I35: Restaurant | Y35: Closed (2026) — now Old Salt Fish & Bagel | AJ35: 2026-06-19 | AK35: CLOSED - drop
A36: 34 | B36: Paseo | C36: Fremont | D36: https://www.paseorestaurants.com | E36: Caribbean | F36: $ | G36: casual-date | H36: Paseo is a Seattle rite of passage — Caribbean sandwiches piled with caramelized onions and slow-roasted pork that inspire citywide devotion. It's a counter-service hole-in-the-wall, not a sit-down affair, but for a casual, messy, deeply happy date over the famous Caribbean Roast, few things beat it. | I36: Restaurant | J36: 4225 Fremont Ave N, Seattle, WA 98103 | K36: (206) 545-7440 | L36: Caribbean sandwiches | M36: Tue-Fri 11am-9pm; Sat to 8; Sun/Mon to 6 | N36: No | O36: Counter service | P36: Y | Q36: N | R36: N | S36: Casual; Iconic; No-frills | T36: Moderate | U36: 2 | V36: Y | X36: 5600+ | Y36: Cult Caribbean sandwich counter; the Caribbean Roast | Z36: Caribbean Roast sandwich | AA36: Pork platos | AB36: $12-18 | AC36: https://www.paseo.com/menu | AD36: HTML | AI36: 2026-06 | AJ36: 2026-06-19 | AK36: Enriched
A37: 35 | B37: Agrodolce | C37: Fremont | D37: https://www.agrodolceseattle.com | E37: Italian | G37: organic;romantic | I37: Restaurant | Y37: Yelp shows CLOSED (Feb 2026); verify before include | AJ37: 2026-06-19 | AK37: Review
A38: 36 | B38: Red Star Taco Bar | C38: Fremont | D38: https://www.redstartacobar.com | E38: Mexican | F38: $$ | G38: casual;fun | H38: Red Star Taco Bar is a 21-plus Fremont taqueria built around eclectic tacos and a serious tequila and frozen-margarita program — carnitas next to Korean BBQ and Bang Bang cauliflower. Loud, fun, and open late, an unpretentious date for two who'd rather split a dozen tacos and a pitcher than dress up. | I38: Restaurant | J38: 513 N 36th St Ste E, Seattle, WA 98103 | K38: (206) 471-5027 | L38: Tacos/Tequila | M38: Sun-Thu 11am-12am; Fri-Sat to 2am | N38: Walk-in | O38: Walk-in (21+) | P38: Y | Q38: Y | R38: Y | S38: Fun; Casual; Late-night | T38: Loud | U38: 3 | V38: Y | X38: 530+ | Y38: Eclectic tacos + tequila, 21+, late-night | Z38: Carnitas tacos | AA38: Frozen margarita | AB38: $12-22 | AC38: https://www.redstartacobar.com/ | AD38: HTML | AI38: 2026-06 | AJ38: 2026-06-19 | AK38: Enriched
A39: 37 | B39: Fiasco | C39: Fremont | D39: https://www.fiascoseattle.com | E39: Italian | G39: neighborhood;wine | I39: Restaurant | Y39: Yelp shows CLOSED (Dec 2025); verify before include | AJ39: 2026-06-19 | AK39: Review
A40: 38 | B40: The Whale Wins | C40: Fremont | D40: https://www.thewhalewins.com | E40: Pacific NW | G40: bright;seasonal | I40: Restaurant | Y40: Permanently closed Oct 2025 | AJ40: 2026-06-19 | AK40: CLOSED - drop
...
